Traceback (most recent call last):
  File "/usr/local/python/3.10.13/lib/python3.10/site-packages/jupyter_cache/executors/utils.py", line 58, in single_nb_execution
    executenb(
  File "/home/codespace/.local/lib/python3.10/site-packages/nbclient/client.py", line 1314, in execute
    return NotebookClient(nb=nb, resources=resources, km=km, **kwargs).execute()
  File "/home/codespace/.local/lib/python3.10/site-packages/jupyter_core/utils/__init__.py", line 165, in wrapped
    return loop.run_until_complete(inner)
  File "/usr/local/python/3.10.13/lib/python3.10/asyncio/base_events.py", line 649, in run_until_complete
    return future.result()
  File "/home/codespace/.local/lib/python3.10/site-packages/nbclient/client.py", line 709, in async_execute
    await self.async_execute_cell(
  File "/home/codespace/.local/lib/python3.10/site-packages/nbclient/client.py", line 1062, in async_execute_cell
    await self._check_raise_for_error(cell, cell_index, exec_reply)
  File "/home/codespace/.local/lib/python3.10/site-packages/nbclient/client.py", line 918, in _check_raise_for_error
    raise CellExecutionError.from_cell_and_msg(cell, exec_reply_content)
nbclient.exceptions.CellExecutionError: An error occurred while executing the following cell:
------------------
df_1 = _deepnote_execute_sql('SELECT * FROM fertility.fertility', 'SQL_0A99A490_95B5_4FD7_86DC_469537FD258A', audit_sql_comment='', sql_cache_mode='cache_disabled')
df_1
------------------


[0;31m---------------------------------------------------------------------------[0m
[0;31mNameError[0m                                 Traceback (most recent call last)
Cell [0;32mIn[1], line 1[0m
[0;32m----> 1[0m df_1 [38;5;241m=[39m [43m_deepnote_execute_sql[49m([38;5;124m'[39m[38;5;124mSELECT * FROM fertility.fertility[39m[38;5;124m'[39m, [38;5;124m'[39m[38;5;124mSQL_0A99A490_95B5_4FD7_86DC_469537FD258A[39m[38;5;124m'[39m, audit_sql_comment[38;5;241m=[39m[38;5;124m'[39m[38;5;124m'[39m, sql_cache_mode[38;5;241m=[39m[38;5;124m'[39m[38;5;124mcache_disabled[39m[38;5;124m'[39m)
[1;32m      2[0m df_1

[0;31mNameError[0m: name '_deepnote_execute_sql' is not defined

